[2024-09-30T07:44:24.121+0000] {local_task_job_runner.py:123} INFO - ::group::Pre task execution logs
[2024-09-30T07:44:24.176+0000] {taskinstance.py:2612} INFO - Dependencies all met for dep_context=non-requeueable deps ti=<TaskInstance: getdata.test scheduled__2024-09-29T00:00:00+00:00 [queued]>
[2024-09-30T07:44:24.189+0000] {taskinstance.py:2612} INFO - Dependencies all met for dep_context=requeueable deps ti=<TaskInstance: getdata.test scheduled__2024-09-29T00:00:00+00:00 [queued]>
[2024-09-30T07:44:24.190+0000] {taskinstance.py:2865} INFO - Starting attempt 1 of 2
[2024-09-30T07:44:24.212+0000] {taskinstance.py:2888} INFO - Executing <Task(PythonOperator): test> on 2024-09-29 00:00:00+00:00
[2024-09-30T07:44:24.215+0000] {standard_task_runner.py:72} INFO - Started process 1123 to run task
[2024-09-30T07:44:24.218+0000] {standard_task_runner.py:104} INFO - Running: ['airflow', 'tasks', 'run', 'getdata', 'test', 'scheduled__2024-09-29T00:00:00+00:00', '--job-id', '46', '--raw', '--subdir', 'DAGS_FOLDER/getdata.py', '--cfg-path', '/tmp/tmpjs6phti3']
[2024-09-30T07:44:24.220+0000] {standard_task_runner.py:105} INFO - Job 46: Subtask test
[2024-09-30T07:44:24.353+0000] {task_command.py:467} INFO - Running <TaskInstance: getdata.test scheduled__2024-09-29T00:00:00+00:00 [running]> on host 2daa23560fcb
[2024-09-30T07:44:24.549+0000] {taskinstance.py:3131} INFO - Exporting env vars: AIRFLOW_CTX_DAG_OWNER='airflow' AIRFLOW_CTX_DAG_ID='getdata' AIRFLOW_CTX_TASK_ID='test' AIRFLOW_CTX_EXECUTION_DATE='2024-09-29T00:00:00+00:00' AIRFLOW_CTX_TRY_NUMBER='1' AIRFLOW_CTX_DAG_RUN_ID='scheduled__2024-09-29T00:00:00+00:00'
[2024-09-30T07:44:24.551+0000] {taskinstance.py:731} INFO - ::endgroup::
[2024-09-30T07:44:24.624+0000] {taskinstance.py:3310} ERROR - Task failed with exception
Traceback (most recent call last):
  File "/home/airflow/.local/lib/python3.10/site-packages/airflow/models/taskinstance.py", line 767, in _execute_task
    result = _execute_callable(context=context, **execute_callable_kwargs)
  File "/home/airflow/.local/lib/python3.10/site-packages/airflow/models/taskinstance.py", line 733, in _execute_callable
    return ExecutionCallableRunner(
  File "/home/airflow/.local/lib/python3.10/site-packages/airflow/utils/operator_helpers.py", line 252, in run
    return self.func(*args, **kwargs)
  File "/home/airflow/.local/lib/python3.10/site-packages/airflow/models/baseoperator.py", line 406, in wrapper
    return func(self, *args, **kwargs)
  File "/home/airflow/.local/lib/python3.10/site-packages/airflow/operators/python.py", line 238, in execute
    return_value = self.execute_callable()
  File "/home/airflow/.local/lib/python3.10/site-packages/airflow/operators/python.py", line 256, in execute_callable
    return runner.run(*self.op_args, **self.op_kwargs)
  File "/home/airflow/.local/lib/python3.10/site-packages/airflow/utils/operator_helpers.py", line 252, in run
    return self.func(*args, **kwargs)
  File "/opt/airflow/dags/getdata.py", line 21, in write_kafka
    app = Application(
  File "/home/airflow/.local/lib/python3.10/site-packages/quixstreams/app.py", line 259, in __init__
    self._config = ApplicationConfig(
  File "/home/airflow/.local/lib/python3.10/site-packages/pydantic_settings/main.py", line 152, in __init__
    super().__init__(
  File "/home/airflow/.local/lib/python3.10/site-packages/pydantic/main.py", line 212, in __init__
    validated_self = self.__pydantic_validator__.validate_python(data, self_instance=self)
pydantic_core._pydantic_core.ValidationError: 1 validation error for ApplicationConfig
broker_address
  Input should be a valid dictionary or instance of ConnectionConfig [type=model_type, input_value={'broker-1:29092', 'broke...9092', 'broker-2:29092'}, input_type=set]
    For further information visit https://errors.pydantic.dev/2.9/v/model_type
[2024-09-30T07:44:24.670+0000] {taskinstance.py:1225} INFO - Marking task as UP_FOR_RETRY. dag_id=getdata, task_id=test, run_id=scheduled__2024-09-29T00:00:00+00:00, execution_date=20240929T000000, start_date=20240930T074424, end_date=20240930T074424
[2024-09-30T07:44:24.706+0000] {taskinstance.py:340} INFO - ::group::Post task execution logs
[2024-09-30T07:44:24.708+0000] {standard_task_runner.py:124} ERROR - Failed to execute job 46 for task test (1 validation error for ApplicationConfig
broker_address
  Input should be a valid dictionary or instance of ConnectionConfig [type=model_type, input_value={'broker-1:29092', 'broke...9092', 'broker-2:29092'}, input_type=set]
    For further information visit https://errors.pydantic.dev/2.9/v/model_type; 1123)
Traceback (most recent call last):
  File "/home/airflow/.local/lib/python3.10/site-packages/airflow/task/task_runner/standard_task_runner.py", line 117, in _start_by_fork
    ret = args.func(args, dag=self.dag)
  File "/home/airflow/.local/lib/python3.10/site-packages/airflow/cli/cli_config.py", line 49, in command
    return func(*args, **kwargs)
  File "/home/airflow/.local/lib/python3.10/site-packages/airflow/utils/cli.py", line 115, in wrapper
    return f(*args, **kwargs)
  File "/home/airflow/.local/lib/python3.10/site-packages/airflow/cli/commands/task_command.py", line 483, in task_run
    task_return_code = _run_task_by_selected_method(args, _dag, ti)
  File "/home/airflow/.local/lib/python3.10/site-packages/airflow/cli/commands/task_command.py", line 256, in _run_task_by_selected_method
    return _run_raw_task(args, ti)
  File "/home/airflow/.local/lib/python3.10/site-packages/airflow/cli/commands/task_command.py", line 341, in _run_raw_task
    return ti._run_raw_task(
  File "/home/airflow/.local/lib/python3.10/site-packages/airflow/utils/session.py", line 97, in wrapper
    return func(*args, session=session, **kwargs)
  File "/home/airflow/.local/lib/python3.10/site-packages/airflow/models/taskinstance.py", line 3004, in _run_raw_task
    return _run_raw_task(
  File "/home/airflow/.local/lib/python3.10/site-packages/airflow/models/taskinstance.py", line 273, in _run_raw_task
    TaskInstance._execute_task_with_callbacks(
  File "/home/airflow/.local/lib/python3.10/site-packages/airflow/models/taskinstance.py", line 3158, in _execute_task_with_callbacks
    result = self._execute_task(context, task_orig)
  File "/home/airflow/.local/lib/python3.10/site-packages/airflow/models/taskinstance.py", line 3182, in _execute_task
    return _execute_task(self, context, task_orig)
  File "/home/airflow/.local/lib/python3.10/site-packages/airflow/models/taskinstance.py", line 767, in _execute_task
    result = _execute_callable(context=context, **execute_callable_kwargs)
  File "/home/airflow/.local/lib/python3.10/site-packages/airflow/models/taskinstance.py", line 733, in _execute_callable
    return ExecutionCallableRunner(
  File "/home/airflow/.local/lib/python3.10/site-packages/airflow/utils/operator_helpers.py", line 252, in run
    return self.func(*args, **kwargs)
  File "/home/airflow/.local/lib/python3.10/site-packages/airflow/models/baseoperator.py", line 406, in wrapper
    return func(self, *args, **kwargs)
  File "/home/airflow/.local/lib/python3.10/site-packages/airflow/operators/python.py", line 238, in execute
    return_value = self.execute_callable()
  File "/home/airflow/.local/lib/python3.10/site-packages/airflow/operators/python.py", line 256, in execute_callable
    return runner.run(*self.op_args, **self.op_kwargs)
  File "/home/airflow/.local/lib/python3.10/site-packages/airflow/utils/operator_helpers.py", line 252, in run
    return self.func(*args, **kwargs)
  File "/opt/airflow/dags/getdata.py", line 21, in write_kafka
    app = Application(
  File "/home/airflow/.local/lib/python3.10/site-packages/quixstreams/app.py", line 259, in __init__
    self._config = ApplicationConfig(
  File "/home/airflow/.local/lib/python3.10/site-packages/pydantic_settings/main.py", line 152, in __init__
    super().__init__(
  File "/home/airflow/.local/lib/python3.10/site-packages/pydantic/main.py", line 212, in __init__
    validated_self = self.__pydantic_validator__.validate_python(data, self_instance=self)
pydantic_core._pydantic_core.ValidationError: 1 validation error for ApplicationConfig
broker_address
  Input should be a valid dictionary or instance of ConnectionConfig [type=model_type, input_value={'broker-1:29092', 'broke...9092', 'broker-2:29092'}, input_type=set]
    For further information visit https://errors.pydantic.dev/2.9/v/model_type
[2024-09-30T07:44:24.727+0000] {local_task_job_runner.py:266} INFO - Task exited with return code 1
[2024-09-30T07:44:24.760+0000] {taskinstance.py:3900} INFO - 0 downstream tasks scheduled from follow-on schedule check
[2024-09-30T07:44:24.766+0000] {local_task_job_runner.py:245} INFO - ::endgroup::
